2025-03-19 21:03:46,552 - instabot version: 0.117.0 (bot) - INFO - Instabot version: 0.117.0 Started
2025-03-19 21:03:46,552 - instabot version: 0.117.0 (bot) - DEBUG - Bot imported from /Users/fenix_systems/Desktop/python-projects/env/lib/python3.11/site-packages/instabot/bot/bot.py
2025-03-19 21:03:46,553 - instabot version: 0.117.0 (api_login) - INFO - Not yet logged in starting: PRE-LOGIN FLOW!
2025-03-19 21:03:46,559 - instabot version: 0.117.0 (api) - WARNING - HTTPSConnectionPool(host='i.instagram.com', port=443): Max retries exceeded with url: /api/v1/accounts/get_prefill_candidates/ (Caused by ProxyError('Unable to connect to proxy', NewConnectionError('<urllib3.connection.HTTPSConnection object at 0x101a71290>: Failed to establish a new connection: [Errno 61] Connection refused')))
2025-03-19 21:03:46,560 - instabot version: 0.117.0 (api) - WARNING - HTTPSConnectionPool(host='i.instagram.com', port=443): Max retries exceeded with url: /api/v1/qe/sync/ (Caused by ProxyError('Unable to connect to proxy', NewConnectionError('<urllib3.connection.HTTPSConnection object at 0x101a73350>: Failed to establish a new connection: [Errno 61] Connection refused')))
2025-03-19 21:03:46,561 - instabot version: 0.117.0 (api) - WARNING - HTTPSConnectionPool(host='i.instagram.com', port=443): Max retries exceeded with url: /api/v1/launcher/sync/ (Caused by ProxyError('Unable to connect to proxy', NewConnectionError('<urllib3.connection.HTTPSConnection object at 0x101a80150>: Failed to establish a new connection: [Errno 61] Connection refused')))
2025-03-19 21:03:46,562 - instabot version: 0.117.0 (api) - WARNING - HTTPSConnectionPool(host='i.instagram.com', port=443): Max retries exceeded with url: /api/v1/accounts/contact_point_prefill/ (Caused by ProxyError('Unable to connect to proxy', NewConnectionError('<urllib3.connection.HTTPSConnection object at 0x101a82910>: Failed to establish a new connection: [Errno 61] Connection refused')))
